INFO:root:Бот стартовал
INFO:apscheduler.scheduler:Scheduler started
INFO:telegram.ext.updater:Received signal 2 (SIGINT), stopping...
INFO:apscheduler.scheduler:Scheduler has been shut down
WARNING:telegram.ext.updater:Exiting immediately!
INFO:root:Бот стартовал
INFO:apscheduler.scheduler:Scheduler started
INFO:telegram.ext.updater:Received signal 2 (SIGINT), stopping...
INFO:apscheduler.scheduler:Scheduler has been shut down
WARNING:telegram.ext.updater:Exiting immediately!
INFO:root:Бот стартовал
INFO:apscheduler.scheduler:Scheduler started
INFO:telegram.ext.updater:Received signal 2 (SIGINT), stopping...
INFO:apscheduler.scheduler:Scheduler has been shut down
WARNING:telegram.ext.updater:Exiting immediately!
INFO:root:Бот стартовал
INFO:apscheduler.scheduler:Scheduler started
ERROR:telegram.ext.dispatcher:No error handlers are registered, logging exception.
Traceback (most recent call last):
  File "/home/vartan/.local/lib/python3.8/site-packages/telegram/ext/dispatcher.py", line 425, in process_update
    handler.handle_update(update, self, check, context)
  File "/home/vartan/.local/lib/python3.8/site-packages/telegram/ext/handler.py", line 145, in handle_update
    return self.callback(update, context)
  File "bot.py", line 16, in get_plane
    update.message.reply_text('user_text=',user_text)
  File "/home/vartan/.local/lib/python3.8/site-packages/telegram/message.py", line 514, in reply_text
    return self.bot.send_message(self.chat_id, *args, **kwargs)
  File "<decorator-gen-2>", line 2, in send_message
  File "/home/vartan/.local/lib/python3.8/site-packages/telegram/bot.py", line 78, in decorator
    result = func(*args, **kwargs)
  File "/home/vartan/.local/lib/python3.8/site-packages/telegram/bot.py", line 382, in send_message
    return self._message('sendMessage', data,  # type: ignore[return-value]
  File "/home/vartan/.local/lib/python3.8/site-packages/telegram/bot.py", line 215, in _message
    result = self._post(endpoint, data, timeout=timeout, api_kwargs=api_kwargs)
  File "/home/vartan/.local/lib/python3.8/site-packages/telegram/bot.py", line 184, in _post
    return self.request.post('{}/{}'.format(self.base_url, endpoint), data=data,
  File "/home/vartan/.local/lib/python3.8/site-packages/telegram/utils/request.py", line 325, in post
    result = self._request_wrapper('POST', url,
  File "/home/vartan/.local/lib/python3.8/site-packages/telegram/utils/request.py", line 250, in _request_wrapper
    raise BadRequest(message)
telegram.error.BadRequest: Unsupported parse_mode
INFO:telegram.ext.updater:Received signal 2 (SIGINT), stopping...
INFO:apscheduler.scheduler:Scheduler has been shut down
WARNING:telegram.ext.updater:Exiting immediately!
INFO:root:Бот стартовал
INFO:apscheduler.scheduler:Scheduler started
INFO:telegram.ext.updater:Received signal 2 (SIGINT), stopping...
INFO:apscheduler.scheduler:Scheduler has been shut down
INFO:root:Бот стартовал
INFO:apscheduler.scheduler:Scheduler started
ERROR:telegram.ext.dispatcher:No error handlers are registered, logging exception.
Traceback (most recent call last):
  File "/home/vartan/.local/lib/python3.8/site-packages/telegram/ext/dispatcher.py", line 425, in process_update
    handler.handle_update(update, self, check, context)
  File "/home/vartan/.local/lib/python3.8/site-packages/telegram/ext/handler.py", line 145, in handle_update
    return self.callback(update, context)
  File "bot.py", line 16, in get_plane
    update.message.reply_text('user_text=',user_text)
  File "/home/vartan/.local/lib/python3.8/site-packages/telegram/message.py", line 514, in reply_text
    return self.bot.send_message(self.chat_id, *args, **kwargs)
  File "<decorator-gen-2>", line 2, in send_message
  File "/home/vartan/.local/lib/python3.8/site-packages/telegram/bot.py", line 78, in decorator
    result = func(*args, **kwargs)
  File "/home/vartan/.local/lib/python3.8/site-packages/telegram/bot.py", line 382, in send_message
    return self._message('sendMessage', data,  # type: ignore[return-value]
  File "/home/vartan/.local/lib/python3.8/site-packages/telegram/bot.py", line 215, in _message
    result = self._post(endpoint, data, timeout=timeout, api_kwargs=api_kwargs)
  File "/home/vartan/.local/lib/python3.8/site-packages/telegram/bot.py", line 184, in _post
    return self.request.post('{}/{}'.format(self.base_url, endpoint), data=data,
  File "/home/vartan/.local/lib/python3.8/site-packages/telegram/utils/request.py", line 325, in post
    result = self._request_wrapper('POST', url,
  File "/home/vartan/.local/lib/python3.8/site-packages/telegram/utils/request.py", line 250, in _request_wrapper
    raise BadRequest(message)
telegram.error.BadRequest: Unsupported parse_mode
INFO:root:Бот стартовал
INFO:apscheduler.scheduler:Scheduler started
ERROR:telegram.ext.dispatcher:No error handlers are registered, logging exception.
Traceback (most recent call last):
  File "/home/vartan/.local/lib/python3.8/site-packages/telegram/ext/dispatcher.py", line 425, in process_update
    handler.handle_update(update, self, check, context)
  File "/home/vartan/.local/lib/python3.8/site-packages/telegram/ext/handler.py", line 145, in handle_update
    return self.callback(update, context)
  File "bot.py", line 20, in get_plane
    update.message.reply_text('user_text=',user_text)
  File "/home/vartan/.local/lib/python3.8/site-packages/telegram/message.py", line 514, in reply_text
    return self.bot.send_message(self.chat_id, *args, **kwargs)
  File "<decorator-gen-2>", line 2, in send_message
  File "/home/vartan/.local/lib/python3.8/site-packages/telegram/bot.py", line 78, in decorator
    result = func(*args, **kwargs)
  File "/home/vartan/.local/lib/python3.8/site-packages/telegram/bot.py", line 382, in send_message
    return self._message('sendMessage', data,  # type: ignore[return-value]
  File "/home/vartan/.local/lib/python3.8/site-packages/telegram/bot.py", line 215, in _message
    result = self._post(endpoint, data, timeout=timeout, api_kwargs=api_kwargs)
  File "/home/vartan/.local/lib/python3.8/site-packages/telegram/bot.py", line 184, in _post
    return self.request.post('{}/{}'.format(self.base_url, endpoint), data=data,
  File "/home/vartan/.local/lib/python3.8/site-packages/telegram/utils/request.py", line 325, in post
    result = self._request_wrapper('POST', url,
  File "/home/vartan/.local/lib/python3.8/site-packages/telegram/utils/request.py", line 250, in _request_wrapper
    raise BadRequest(message)
telegram.error.BadRequest: Unsupported parse_mode
INFO:root:Бот стартовал
INFO:apscheduler.scheduler:Scheduler started
INFO:telegram.ext.updater:Received signal 2 (SIGINT), stopping...
INFO:apscheduler.scheduler:Scheduler has been shut down
WARNING:telegram.ext.updater:Exiting immediately!
INFO:root:Бот стартовал
INFO:apscheduler.scheduler:Scheduler started
INFO:root:Бот стартовал
INFO:apscheduler.scheduler:Scheduler started
INFO:root:Бот стартовал
INFO:apscheduler.scheduler:Scheduler started
ERROR:telegram.ext.dispatcher:No error handlers are registered, logging exception.
Traceback (most recent call last):
  File "/home/vartan/.local/lib/python3.8/site-packages/telegram/ext/dispatcher.py", line 425, in process_update
    handler.handle_update(update, self, check, context)
  File "/home/vartan/.local/lib/python3.8/site-packages/telegram/ext/handler.py", line 145, in handle_update
    return self.callback(update, context)
  File "bot.py", line 19, in get_plane
    b=(ephem._libastro.builtin_planets())
AttributeError: module 'ephem' has no attribute '_libastro'
INFO:telegram.ext.updater:Received signal 2 (SIGINT), stopping...
INFO:apscheduler.scheduler:Scheduler has been shut down
WARNING:telegram.ext.updater:Exiting immediately!
INFO:root:Бот стартовал
INFO:apscheduler.scheduler:Scheduler started
ERROR:telegram.ext.dispatcher:No error handlers are registered, logging exception.
Traceback (most recent call last):
  File "/home/vartan/.local/lib/python3.8/site-packages/telegram/ext/dispatcher.py", line 425, in process_update
    handler.handle_update(update, self, check, context)
  File "/home/vartan/.local/lib/python3.8/site-packages/telegram/ext/handler.py", line 145, in handle_update
    return self.callback(update, context)
  File "bot.py", line 19, in get_plane
    b=(ephem._libastro.builtin_planets())
AttributeError: module 'ephem' has no attribute '_libastro'
INFO:root:Бот стартовал
INFO:apscheduler.scheduler:Scheduler started
ERROR:telegram.ext.dispatcher:No error handlers are registered, logging exception.
Traceback (most recent call last):
  File "/home/vartan/.local/lib/python3.8/site-packages/telegram/ext/dispatcher.py", line 425, in process_update
    handler.handle_update(update, self, check, context)
  File "/home/vartan/.local/lib/python3.8/site-packages/telegram/ext/handler.py", line 145, in handle_update
    return self.callback(update, context)
  File "bot.py", line 19, in get_plane
    b=(ephem._libastro.builtin_planets())
AttributeError: module 'ephem' has no attribute '_libastro'
ERROR:telegram.ext.dispatcher:No error handlers are registered, logging exception.
Traceback (most recent call last):
  File "/home/vartan/.local/lib/python3.8/site-packages/telegram/ext/dispatcher.py", line 425, in process_update
    handler.handle_update(update, self, check, context)
  File "/home/vartan/.local/lib/python3.8/site-packages/telegram/ext/handler.py", line 145, in handle_update
    return self.callback(update, context)
  File "bot.py", line 19, in get_plane
    b=(ephem._libastro.builtin_planets())
AttributeError: module 'ephem' has no attribute '_libastro'
INFO:root:Бот стартовал
INFO:apscheduler.scheduler:Scheduler started
ERROR:telegram.ext.dispatcher:No error handlers are registered, logging exception.
Traceback (most recent call last):
  File "/home/vartan/.local/lib/python3.8/site-packages/telegram/ext/dispatcher.py", line 425, in process_update
    handler.handle_update(update, self, check, context)
  File "/home/vartan/.local/lib/python3.8/site-packages/telegram/ext/handler.py", line 145, in handle_update
    return self.callback(update, context)
  File "bot.py", line 35, in get_plane
    update.message.reply_text('user_text=',user_text)
  File "/home/vartan/.local/lib/python3.8/site-packages/telegram/message.py", line 514, in reply_text
    return self.bot.send_message(self.chat_id, *args, **kwargs)
  File "<decorator-gen-2>", line 2, in send_message
  File "/home/vartan/.local/lib/python3.8/site-packages/telegram/bot.py", line 78, in decorator
    result = func(*args, **kwargs)
  File "/home/vartan/.local/lib/python3.8/site-packages/telegram/bot.py", line 382, in send_message
    return self._message('sendMessage', data,  # type: ignore[return-value]
  File "/home/vartan/.local/lib/python3.8/site-packages/telegram/bot.py", line 215, in _message
    result = self._post(endpoint, data, timeout=timeout, api_kwargs=api_kwargs)
  File "/home/vartan/.local/lib/python3.8/site-packages/telegram/bot.py", line 184, in _post
    return self.request.post('{}/{}'.format(self.base_url, endpoint), data=data,
  File "/home/vartan/.local/lib/python3.8/site-packages/telegram/utils/request.py", line 325, in post
    result = self._request_wrapper('POST', url,
  File "/home/vartan/.local/lib/python3.8/site-packages/telegram/utils/request.py", line 250, in _request_wrapper
    raise BadRequest(message)
telegram.error.BadRequest: Unsupported parse_mode
INFO:telegram.ext.updater:Received signal 2 (SIGINT), stopping...
INFO:apscheduler.scheduler:Scheduler has been shut down
INFO:root:Бот стартовал
INFO:apscheduler.scheduler:Scheduler started
ERROR:telegram.ext.dispatcher:No error handlers are registered, logging exception.
Traceback (most recent call last):
  File "/home/vartan/.local/lib/python3.8/site-packages/telegram/ext/dispatcher.py", line 425, in process_update
    handler.handle_update(update, self, check, context)
  File "/home/vartan/.local/lib/python3.8/site-packages/telegram/ext/handler.py", line 145, in handle_update
    return self.callback(update, context)
  File "bot.py", line 35, in get_plane
    update.message.reply_text('user_text=',user_text)
  File "/home/vartan/.local/lib/python3.8/site-packages/telegram/message.py", line 514, in reply_text
    return self.bot.send_message(self.chat_id, *args, **kwargs)
  File "<decorator-gen-2>", line 2, in send_message
  File "/home/vartan/.local/lib/python3.8/site-packages/telegram/bot.py", line 78, in decorator
    result = func(*args, **kwargs)
  File "/home/vartan/.local/lib/python3.8/site-packages/telegram/bot.py", line 382, in send_message
    return self._message('sendMessage', data,  # type: ignore[return-value]
  File "/home/vartan/.local/lib/python3.8/site-packages/telegram/bot.py", line 215, in _message
    result = self._post(endpoint, data, timeout=timeout, api_kwargs=api_kwargs)
  File "/home/vartan/.local/lib/python3.8/site-packages/telegram/bot.py", line 184, in _post
    return self.request.post('{}/{}'.format(self.base_url, endpoint), data=data,
  File "/home/vartan/.local/lib/python3.8/site-packages/telegram/utils/request.py", line 325, in post
    result = self._request_wrapper('POST', url,
  File "/home/vartan/.local/lib/python3.8/site-packages/telegram/utils/request.py", line 250, in _request_wrapper
    raise BadRequest(message)
telegram.error.BadRequest: Unsupported parse_mode
INFO:root:Бот стартовал
INFO:apscheduler.scheduler:Scheduler started
ERROR:telegram.ext.dispatcher:No error handlers are registered, logging exception.
Traceback (most recent call last):
  File "/home/vartan/.local/lib/python3.8/site-packages/telegram/ext/dispatcher.py", line 425, in process_update
    handler.handle_update(update, self, check, context)
  File "/home/vartan/.local/lib/python3.8/site-packages/telegram/ext/handler.py", line 145, in handle_update
    return self.callback(update, context)
  File "bot.py", line 19, in get_plane
    b=(ephem._libastro.builtin_planets())
AttributeError: module 'ephem' has no attribute '_libastro'
INFO:root:Бот стартовал
INFO:apscheduler.scheduler:Scheduler started
ERROR:telegram.ext.dispatcher:No error handlers are registered, logging exception.
Traceback (most recent call last):
  File "/home/vartan/.local/lib/python3.8/site-packages/telegram/ext/dispatcher.py", line 425, in process_update
    handler.handle_update(update, self, check, context)
  File "/home/vartan/.local/lib/python3.8/site-packages/telegram/ext/handler.py", line 145, in handle_update
    return self.callback(update, context)
  File "bot.py", line 19, in get_plane
    b=(ephem._libastro.builtin_planets())
AttributeError: module 'ephem' has no attribute '_libastro'
INFO:root:Бот стартовал
INFO:apscheduler.scheduler:Scheduler started
ERROR:telegram.ext.dispatcher:No error handlers are registered, logging exception.
Traceback (most recent call last):
  File "/home/vartan/.local/lib/python3.8/site-packages/telegram/ext/dispatcher.py", line 425, in process_update
    handler.handle_update(update, self, check, context)
  File "/home/vartan/.local/lib/python3.8/site-packages/telegram/ext/handler.py", line 145, in handle_update
    return self.callback(update, context)
  File "bot.py", line 35, in get_plane
    update.message.reply_text('user_text=',user_text)
  File "/home/vartan/.local/lib/python3.8/site-packages/telegram/message.py", line 514, in reply_text
    return self.bot.send_message(self.chat_id, *args, **kwargs)
  File "<decorator-gen-2>", line 2, in send_message
  File "/home/vartan/.local/lib/python3.8/site-packages/telegram/bot.py", line 78, in decorator
    result = func(*args, **kwargs)
  File "/home/vartan/.local/lib/python3.8/site-packages/telegram/bot.py", line 382, in send_message
    return self._message('sendMessage', data,  # type: ignore[return-value]
  File "/home/vartan/.local/lib/python3.8/site-packages/telegram/bot.py", line 215, in _message
    result = self._post(endpoint, data, timeout=timeout, api_kwargs=api_kwargs)
  File "/home/vartan/.local/lib/python3.8/site-packages/telegram/bot.py", line 184, in _post
    return self.request.post('{}/{}'.format(self.base_url, endpoint), data=data,
  File "/home/vartan/.local/lib/python3.8/site-packages/telegram/utils/request.py", line 325, in post
    result = self._request_wrapper('POST', url,
  File "/home/vartan/.local/lib/python3.8/site-packages/telegram/utils/request.py", line 250, in _request_wrapper
    raise BadRequest(message)
telegram.error.BadRequest: Unsupported parse_mode
INFO:root:Бот стартовал
INFO:apscheduler.scheduler:Scheduler started
WARNING:telegram.vendor.ptb_urllib3.urllib3.connectionpool:Retrying (Retry(total=2, connect=None, read=None, redirect=None)) after connection broken by 'ConnectTimeoutError(<telegram.vendor.ptb_urllib3.urllib3.connectionpool.HTTPSConnectionPool object at 0x7f0213e326d0>, 'Connect timed out. (connect timeout=5.0)')': /bot1434687120:AAGfcSgquJDQQyE6uXdbcvn35vSI9YLoUZg/getMe
INFO:root:Бот стартовал
INFO:apscheduler.scheduler:Scheduler started
INFO:root:Бот стартовал
INFO:apscheduler.scheduler:Scheduler started
ERROR:telegram.ext.dispatcher:No error handlers are registered, logging exception.
Traceback (most recent call last):
  File "/home/vartan/.local/lib/python3.8/site-packages/telegram/ext/dispatcher.py", line 425, in process_update
    handler.handle_update(update, self, check, context)
  File "/home/vartan/.local/lib/python3.8/site-packages/telegram/ext/handler.py", line 145, in handle_update
    return self.callback(update, context)
  File "bot.py", line 34, in get_plane
    print('!!!!=',ephem._libastro.builtin_planets())
AttributeError: module 'ephem' has no attribute '_libastro'
ERROR:telegram.ext.dispatcher:No error handlers are registered, logging exception.
Traceback (most recent call last):
  File "/home/vartan/.local/lib/python3.8/site-packages/telegram/ext/dispatcher.py", line 425, in process_update
    handler.handle_update(update, self, check, context)
  File "/home/vartan/.local/lib/python3.8/site-packages/telegram/ext/handler.py", line 145, in handle_update
    return self.callback(update, context)
  File "bot.py", line 34, in get_plane
    print('!!!!=',ephem._libastro.builtin_planets())
AttributeError: module 'ephem' has no attribute '_libastro'
INFO:root:Бот стартовал
INFO:apscheduler.scheduler:Scheduler started
ERROR:telegram.ext.dispatcher:No error handlers are registered, logging exception.
Traceback (most recent call last):
  File "/home/vartan/.local/lib/python3.8/site-packages/telegram/ext/dispatcher.py", line 425, in process_update
    handler.handle_update(update, self, check, context)
  File "/home/vartan/.local/lib/python3.8/site-packages/telegram/ext/handler.py", line 145, in handle_update
    return self.callback(update, context)
  File "bot.py", line 15, in get_plane
    user_text = str(update.message.text)
AttributeError: 'NoneType' object has no attribute 'text'
INFO:root:Бот стартовал
INFO:apscheduler.scheduler:Scheduler started
ERROR:telegram.ext.dispatcher:No error handlers are registered, logging exception.
Traceback (most recent call last):
  File "/home/vartan/.local/lib/python3.8/site-packages/telegram/ext/dispatcher.py", line 425, in process_update
    handler.handle_update(update, self, check, context)
  File "/home/vartan/.local/lib/python3.8/site-packages/telegram/ext/handler.py", line 145, in handle_update
    return self.callback(update, context)
  File "bot.py", line 20, in get_plane
    bb=getattr(ephem, user_text_2)
TypeError: getattr(): attribute name must be string
INFO:root:Бот стартовал
INFO:apscheduler.scheduler:Scheduler started
ERROR:telegram.ext.dispatcher:No error handlers are registered, logging exception.
Traceback (most recent call last):
  File "/home/vartan/.local/lib/python3.8/site-packages/telegram/ext/dispatcher.py", line 425, in process_update
    handler.handle_update(update, self, check, context)
  File "/home/vartan/.local/lib/python3.8/site-packages/telegram/ext/handler.py", line 145, in handle_update
    return self.callback(update, context)
  File "bot.py", line 24, in get_plane
    bb_new=bb(a)
NameError: name 'bb' is not defined
INFO:root:Бот стартовал
INFO:apscheduler.scheduler:Scheduler started
ERROR:telegram.ext.dispatcher:No error handlers are registered, logging exception.
Traceback (most recent call last):
  File "/home/vartan/.local/lib/python3.8/site-packages/telegram/ext/dispatcher.py", line 425, in process_update
    handler.handle_update(update, self, check, context)
  File "/home/vartan/.local/lib/python3.8/site-packages/telegram/ext/handler.py", line 145, in handle_update
    return self.callback(update, context)
  File "bot.py", line 15, in get_plane
    user_text = str(update.message.text)
AttributeError: 'NoneType' object has no attribute 'text'
INFO:root:Бот стартовал
INFO:apscheduler.scheduler:Scheduler started
INFO:root:Бот стартовал
INFO:apscheduler.scheduler:Scheduler started
ERROR:telegram.ext.dispatcher:No error handlers are registered, logging exception.
Traceback (most recent call last):
  File "/home/vartan/.local/lib/python3.8/site-packages/telegram/ext/dispatcher.py", line 425, in process_update
    handler.handle_update(update, self, check, context)
  File "/home/vartan/.local/lib/python3.8/site-packages/telegram/ext/handler.py", line 145, in handle_update
    return self.callback(update, context)
  File "bot.py", line 15, in get_plane
    user_text = str(update.message.text)
AttributeError: 'NoneType' object has no attribute 'text'
INFO:root:Бот стартовал
INFO:apscheduler.scheduler:Scheduler started
ERROR:telegram.ext.dispatcher:No error handlers are registered, logging exception.
Traceback (most recent call last):
  File "/home/vartan/.local/lib/python3.8/site-packages/telegram/ext/dispatcher.py", line 425, in process_update
    handler.handle_update(update, self, check, context)
  File "/home/vartan/.local/lib/python3.8/site-packages/telegram/ext/handler.py", line 145, in handle_update
    return self.callback(update, context)
  File "bot.py", line 45, in get_plane
    update.message.reply_text('user_text=',user_text)
  File "/home/vartan/.local/lib/python3.8/site-packages/telegram/message.py", line 514, in reply_text
    return self.bot.send_message(self.chat_id, *args, **kwargs)
  File "<decorator-gen-2>", line 2, in send_message
  File "/home/vartan/.local/lib/python3.8/site-packages/telegram/bot.py", line 78, in decorator
    result = func(*args, **kwargs)
  File "/home/vartan/.local/lib/python3.8/site-packages/telegram/bot.py", line 382, in send_message
    return self._message('sendMessage', data,  # type: ignore[return-value]
  File "/home/vartan/.local/lib/python3.8/site-packages/telegram/bot.py", line 215, in _message
    result = self._post(endpoint, data, timeout=timeout, api_kwargs=api_kwargs)
  File "/home/vartan/.local/lib/python3.8/site-packages/telegram/bot.py", line 184, in _post
    return self.request.post('{}/{}'.format(self.base_url, endpoint), data=data,
  File "/home/vartan/.local/lib/python3.8/site-packages/telegram/utils/request.py", line 325, in post
    result = self._request_wrapper('POST', url,
  File "/home/vartan/.local/lib/python3.8/site-packages/telegram/utils/request.py", line 250, in _request_wrapper
    raise BadRequest(message)
telegram.error.BadRequest: Unsupported parse_mode
INFO:root:Бот стартовал
INFO:apscheduler.scheduler:Scheduler started
ERROR:telegram.ext.dispatcher:No error handlers are registered, logging exception.
Traceback (most recent call last):
  File "/home/vartan/.local/lib/python3.8/site-packages/telegram/ext/dispatcher.py", line 425, in process_update
    handler.handle_update(update, self, check, context)
  File "/home/vartan/.local/lib/python3.8/site-packages/telegram/ext/handler.py", line 145, in handle_update
    return self.callback(update, context)
  File "bot.py", line 22, in get_plane
    bb=getattr(ephem, str(user_text_2[1]))
AttributeError: module 'ephem' has no attribute 'Mars'
INFO:root:Бот стартовал
INFO:apscheduler.scheduler:Scheduler started
ERROR:telegram.ext.dispatcher:No error handlers are registered, logging exception.
Traceback (most recent call last):
  File "/home/vartan/.local/lib/python3.8/site-packages/telegram/ext/dispatcher.py", line 425, in process_update
    handler.handle_update(update, self, check, context)
  File "/home/vartan/.local/lib/python3.8/site-packages/telegram/ext/handler.py", line 145, in handle_update
    return self.callback(update, context)
  File "bot.py", line 22, in get_plane
    bb=getattr(ephem, str(user_text_2[1]))
AttributeError: module 'ephem' has no attribute 'Mars'
INFO:root:Бот стартовал
INFO:apscheduler.scheduler:Scheduler started
ERROR:telegram.ext.dispatcher:No error handlers are registered, logging exception.
Traceback (most recent call last):
  File "/home/vartan/.local/lib/python3.8/site-packages/telegram/ext/dispatcher.py", line 425, in process_update
    handler.handle_update(update, self, check, context)
  File "/home/vartan/.local/lib/python3.8/site-packages/telegram/ext/handler.py", line 145, in handle_update
    return self.callback(update, context)
  File "bot.py", line 18, in get_plane
    print(getattr(ephem, str(user_text_2[1])))
AttributeError: module 'ephem' has no attribute 'Mars'
INFO:root:Бот стартовал
INFO:apscheduler.scheduler:Scheduler started
ERROR:telegram.ext.dispatcher:No error handlers are registered, logging exception.
Traceback (most recent call last):
  File "/home/vartan/.local/lib/python3.8/site-packages/telegram/ext/dispatcher.py", line 425, in process_update
    handler.handle_update(update, self, check, context)
  File "/home/vartan/.local/lib/python3.8/site-packages/telegram/ext/handler.py", line 145, in handle_update
    return self.callback(update, context)
  File "bot.py", line 22, in get_plane
    bb=getattr(ephem, str(user_text_2[1]))
AttributeError: module 'ephem' has no attribute 'Mars'
INFO:root:Бот стартовал
INFO:apscheduler.scheduler:Scheduler started
ERROR:telegram.ext.dispatcher:No error handlers are registered, logging exception.
Traceback (most recent call last):
  File "/home/vartan/.local/lib/python3.8/site-packages/telegram/ext/dispatcher.py", line 425, in process_update
    handler.handle_update(update, self, check, context)
  File "/home/vartan/.local/lib/python3.8/site-packages/telegram/ext/handler.py", line 145, in handle_update
    return self.callback(update, context)
  File "bot.py", line 21, in get_plane
    a_name_palnet=ephem.star(str(user_text_2[1]))
AttributeError: module 'ephem' has no attribute 'star'
INFO:root:Бот стартовал
INFO:apscheduler.scheduler:Scheduler started
ERROR:telegram.ext.dispatcher:No error handlers are registered, logging exception.
Traceback (most recent call last):
  File "/home/vartan/.local/lib/python3.8/site-packages/telegram/ext/dispatcher.py", line 425, in process_update
    handler.handle_update(update, self, check, context)
  File "/home/vartan/.local/lib/python3.8/site-packages/telegram/ext/handler.py", line 145, in handle_update
    return self.callback(update, context)
  File "bot.py", line 21, in get_plane
    a_name_palnet=ephem.star((user_text_2[1]))
AttributeError: module 'ephem' has no attribute 'star'
ERROR:telegram.ext.dispatcher:No error handlers are registered, logging exception.
Traceback (most recent call last):
  File "/home/vartan/.local/lib/python3.8/site-packages/telegram/ext/dispatcher.py", line 425, in process_update
    handler.handle_update(update, self, check, context)
  File "/home/vartan/.local/lib/python3.8/site-packages/telegram/ext/handler.py", line 145, in handle_update
    return self.callback(update, context)
  File "bot.py", line 21, in get_plane
    a_name_palnet=ephem.star((user_text_2[1]))
AttributeError: module 'ephem' has no attribute 'star'
INFO:root:Бот стартовал
INFO:apscheduler.scheduler:Scheduler started
ERROR:telegram.ext.dispatcher:No error handlers are registered, logging exception.
Traceback (most recent call last):
  File "/home/vartan/.local/lib/python3.8/site-packages/telegram/ext/dispatcher.py", line 425, in process_update
    handler.handle_update(update, self, check, context)
  File "/home/vartan/.local/lib/python3.8/site-packages/telegram/ext/handler.py", line 145, in handle_update
    return self.callback(update, context)
  File "bot.py", line 21, in get_plane
    a_name_palnet=ephem.star((user_text_2[1]))
AttributeError: module 'ephem' has no attribute 'star'
INFO:root:Бот стартовал
INFO:apscheduler.scheduler:Scheduler started
ERROR:telegram.ext.dispatcher:No error handlers are registered, logging exception.
Traceback (most recent call last):
  File "/home/vartan/.local/lib/python3.8/site-packages/telegram/ext/dispatcher.py", line 425, in process_update
    handler.handle_update(update, self, check, context)
  File "/home/vartan/.local/lib/python3.8/site-packages/telegram/ext/handler.py", line 145, in handle_update
    return self.callback(update, context)
  File "bot.py", line 22, in get_plane
    a_name_palnet=ephem.star((user_text_2[1]))
AttributeError: module 'ephem' has no attribute 'star'
INFO:root:Бот стартовал
INFO:apscheduler.scheduler:Scheduler started
ERROR:telegram.ext.dispatcher:No error handlers are registered, logging exception.
Traceback (most recent call last):
  File "/home/vartan/.local/lib/python3.8/site-packages/telegram/ext/dispatcher.py", line 425, in process_update
    handler.handle_update(update, self, check, context)
  File "/home/vartan/.local/lib/python3.8/site-packages/telegram/ext/handler.py", line 145, in handle_update
    return self.callback(update, context)
  File "bot.py", line 22, in get_plane
    a_name_palnet=ephem.star(str(user_text_2[1]))
AttributeError: module 'ephem' has no attribute 'star'
INFO:root:Бот стартовал
INFO:apscheduler.scheduler:Scheduler started
ERROR:telegram.ext.dispatcher:No error handlers are registered, logging exception.
Traceback (most recent call last):
  File "/home/vartan/.local/lib/python3.8/site-packages/telegram/ext/dispatcher.py", line 425, in process_update
    handler.handle_update(update, self, check, context)
  File "/home/vartan/.local/lib/python3.8/site-packages/telegram/ext/handler.py", line 145, in handle_update
    return self.callback(update, context)
  File "bot.py", line 23, in get_plane
    mars=ephem.Mars(a)
AttributeError: module 'ephem' has no attribute 'Mars'
ERROR:telegram.ext.dispatcher:No error handlers are registered, logging exception.
Traceback (most recent call last):
  File "/home/vartan/.local/lib/python3.8/site-packages/telegram/ext/dispatcher.py", line 425, in process_update
    handler.handle_update(update, self, check, context)
  File "/home/vartan/.local/lib/python3.8/site-packages/telegram/ext/handler.py", line 145, in handle_update
    return self.callback(update, context)
  File "bot.py", line 22, in get_plane
    if user_text_2[1]== 'Mars':
IndexError: list index out of range
INFO:root:Бот стартовал
INFO:apscheduler.scheduler:Scheduler started
ERROR:telegram.ext.dispatcher:No error handlers are registered, logging exception.
Traceback (most recent call last):
  File "/home/vartan/.local/lib/python3.8/site-packages/telegram/ext/dispatcher.py", line 425, in process_update
    handler.handle_update(update, self, check, context)
  File "/home/vartan/.local/lib/python3.8/site-packages/telegram/ext/handler.py", line 145, in handle_update
    return self.callback(update, context)
  File "bot.py", line 23, in get_plane
    mars=ephem.Mars(a)
AttributeError: module 'ephem' has no attribute 'Mars'
ERROR:telegram.ext.dispatcher:No error handlers are registered, logging exception.
Traceback (most recent call last):
  File "/home/vartan/.local/lib/python3.8/site-packages/telegram/ext/dispatcher.py", line 425, in process_update
    handler.handle_update(update, self, check, context)
  File "/home/vartan/.local/lib/python3.8/site-packages/telegram/ext/handler.py", line 145, in handle_update
    return self.callback(update, context)
  File "bot.py", line 69, in get_plane
    mars=ephem.Moon(a)
AttributeError: module 'ephem' has no attribute 'Moon'
INFO:root:Бот стартовал
INFO:apscheduler.scheduler:Scheduler started
ERROR:telegram.ext.dispatcher:No error handlers are registered, logging exception.
Traceback (most recent call last):
  File "/home/vartan/.local/lib/python3.8/site-packages/telegram/ext/dispatcher.py", line 425, in process_update
    handler.handle_update(update, self, check, context)
  File "/home/vartan/.local/lib/python3.8/site-packages/telegram/ext/handler.py", line 145, in handle_update
    return self.callback(update, context)
  File "bot.py", line 23, in get_plane
    mars=ephem.Mars(a)
AttributeError: module 'ephem' has no attribute 'Mars'
ERROR:telegram.ext.dispatcher:No error handlers are registered, logging exception.
Traceback (most recent call last):
  File "/home/vartan/.local/lib/python3.8/site-packages/telegram/ext/dispatcher.py", line 425, in process_update
    handler.handle_update(update, self, check, context)
  File "/home/vartan/.local/lib/python3.8/site-packages/telegram/ext/handler.py", line 145, in handle_update
    return self.callback(update, context)
  File "bot.py", line 15, in get_plane
    user_text = str(update.message.text)
AttributeError: 'NoneType' object has no attribute 'text'
INFO:root:Бот стартовал
INFO:apscheduler.scheduler:Scheduler started
INFO:root:Бот стартовал
INFO:apscheduler.scheduler:Scheduler started
INFO:root:Бот стартовал
INFO:apscheduler.scheduler:Scheduler started
ERROR:telegram.ext.dispatcher:No error handlers are registered, logging exception.
Traceback (most recent call last):
  File "/home/vartan/.local/lib/python3.8/site-packages/telegram/ext/dispatcher.py", line 425, in process_update
    handler.handle_update(update, self, check, context)
  File "/home/vartan/.local/lib/python3.8/site-packages/telegram/ext/handler.py", line 145, in handle_update
    return self.callback(update, context)
  File "bot.py", line 65, in get_plane
    mars=ephem.Sun(a)
AttributeError: module 'ephem' has no attribute 'Sun'
INFO:root:Бот стартовал
INFO:apscheduler.scheduler:Scheduler started
ERROR:telegram.ext.dispatcher:No error handlers are registered, logging exception.
Traceback (most recent call last):
  File "/home/vartan/.local/lib/python3.8/site-packages/telegram/ext/dispatcher.py", line 425, in process_update
    handler.handle_update(update, self, check, context)
  File "/home/vartan/.local/lib/python3.8/site-packages/telegram/ext/handler.py", line 145, in handle_update
    return self.callback(update, context)
  File "bot.py", line 65, in get_plane
    mars=ephem.Sun(a)
AttributeError: module 'ephem' has no attribute 'Sun'
INFO:root:Бот стартовал
INFO:apscheduler.scheduler:Scheduler started
ERROR:telegram.ext.dispatcher:No error handlers are registered, logging exception.
Traceback (most recent call last):
  File "/home/vartan/.local/lib/python3.8/site-packages/telegram/ext/dispatcher.py", line 425, in process_update
    handler.handle_update(update, self, check, context)
  File "/home/vartan/.local/lib/python3.8/site-packages/telegram/ext/handler.py", line 145, in handle_update
    return self.callback(update, context)
  File "bot.py", line 66, in get_plane
    mars=ephem.Sun(a)
AttributeError: module 'ephem' has no attribute 'Sun'
INFO:root:Бот стартовал
INFO:apscheduler.scheduler:Scheduler started
ERROR:telegram.ext.dispatcher:No error handlers are registered, logging exception.
Traceback (most recent call last):
  File "/home/vartan/.local/lib/python3.8/site-packages/telegram/ext/dispatcher.py", line 425, in process_update
    handler.handle_update(update, self, check, context)
  File "/home/vartan/.local/lib/python3.8/site-packages/telegram/ext/handler.py", line 145, in handle_update
    return self.callback(update, context)
  File "bot.py", line 67, in get_plane
    mars=ephem.Sun(a)
AttributeError: module 'ephem' has no attribute 'Sun'
INFO:root:Бот стартовал
INFO:apscheduler.scheduler:Scheduler started
ERROR:telegram.ext.dispatcher:No error handlers are registered, logging exception.
Traceback (most recent call last):
  File "/home/vartan/.local/lib/python3.8/site-packages/telegram/ext/dispatcher.py", line 425, in process_update
    handler.handle_update(update, self, check, context)
  File "/home/vartan/.local/lib/python3.8/site-packages/telegram/ext/handler.py", line 145, in handle_update
    return self.callback(update, context)
  File "bot.py", line 67, in get_plane
    mars=ephem.Sun(a)
AttributeError: module 'ephem' has no attribute 'Sun'
INFO:root:Бот стартовал
INFO:apscheduler.scheduler:Scheduler started
ERROR:telegram.ext.dispatcher:No error handlers are registered, logging exception.
Traceback (most recent call last):
  File "/home/vartan/.local/lib/python3.8/site-packages/telegram/ext/dispatcher.py", line 425, in process_update
    handler.handle_update(update, self, check, context)
  File "/home/vartan/.local/lib/python3.8/site-packages/telegram/ext/handler.py", line 145, in handle_update
    return self.callback(update, context)
  File "bot.py", line 67, in get_plane
    mars=ephem.Sun(a)
AttributeError: module 'ephem' has no attribute 'Sun'
INFO:root:Бот стартовал
INFO:apscheduler.scheduler:Scheduler started
ERROR:telegram.ext.dispatcher:No error handlers are registered, logging exception.
Traceback (most recent call last):
  File "/home/vartan/.local/lib/python3.8/site-packages/telegram/ext/dispatcher.py", line 425, in process_update
    handler.handle_update(update, self, check, context)
  File "/home/vartan/.local/lib/python3.8/site-packages/telegram/ext/handler.py", line 145, in handle_update
    return self.callback(update, context)
  File "bot.py", line 67, in get_plane
    mars=ephem.Sun(a)
AttributeError: module 'ephem' has no attribute 'Sun'
INFO:root:Бот стартовал
INFO:apscheduler.scheduler:Scheduler started
ERROR:telegram.ext.dispatcher:No error handlers are registered, logging exception.
Traceback (most recent call last):
  File "/home/vartan/.local/lib/python3.8/site-packages/telegram/ext/dispatcher.py", line 425, in process_update
    handler.handle_update(update, self, check, context)
  File "/home/vartan/.local/lib/python3.8/site-packages/telegram/ext/handler.py", line 145, in handle_update
    return self.callback(update, context)
  File "bot.py", line 67, in get_plane
    mars=ephem.Sun(a)
AttributeError: module 'ephem' has no attribute 'Sun'
INFO:root:Бот стартовал
INFO:apscheduler.scheduler:Scheduler started
ERROR:telegram.ext.dispatcher:No error handlers are registered, logging exception.
Traceback (most recent call last):
  File "/home/vartan/.local/lib/python3.8/site-packages/telegram/ext/dispatcher.py", line 425, in process_update
    handler.handle_update(update, self, check, context)
  File "/home/vartan/.local/lib/python3.8/site-packages/telegram/ext/handler.py", line 145, in handle_update
    return self.callback(update, context)
  File "bot.py", line 67, in get_plane
    mars=ephem.Sun(a)
AttributeError: module 'ephem' has no attribute 'Sun'
INFO:root:Бот стартовал
INFO:apscheduler.scheduler:Scheduler started
ERROR:telegram.ext.dispatcher:No error handlers are registered, logging exception.
Traceback (most recent call last):
  File "/home/vartan/.local/lib/python3.8/site-packages/telegram/ext/dispatcher.py", line 425, in process_update
    handler.handle_update(update, self, check, context)
  File "/home/vartan/.local/lib/python3.8/site-packages/telegram/ext/handler.py", line 145, in handle_update
    return self.callback(update, context)
  File "bot.py", line 67, in get_plane
    mars=ephem.Sun(a)
AttributeError: module 'ephem' has no attribute 'Sun'
INFO:root:Бот стартовал
INFO:apscheduler.scheduler:Scheduler started
ERROR:telegram.ext.dispatcher:No error handlers are registered, logging exception.
Traceback (most recent call last):
  File "/home/vartan/.local/lib/python3.8/site-packages/telegram/ext/dispatcher.py", line 425, in process_update
    handler.handle_update(update, self, check, context)
  File "/home/vartan/.local/lib/python3.8/site-packages/telegram/ext/handler.py", line 145, in handle_update
    return self.callback(update, context)
  File "bot.py", line 68, in get_plane
    mars=ephem.Sun(str(a))
AttributeError: module 'ephem' has no attribute 'Sun'
INFO:root:Бот стартовал
INFO:apscheduler.scheduler:Scheduler started
ERROR:telegram.ext.dispatcher:No error handlers are registered, logging exception.
Traceback (most recent call last):
  File "/home/vartan/.local/lib/python3.8/site-packages/telegram/ext/dispatcher.py", line 425, in process_update
    handler.handle_update(update, self, check, context)
  File "/home/vartan/.local/lib/python3.8/site-packages/telegram/ext/handler.py", line 145, in handle_update
    return self.callback(update, context)
  File "bot.py", line 68, in get_plane
    mars=ephem.Sun()
AttributeError: module 'ephem' has no attribute 'Sun'
INFO:root:Бот стартовал
INFO:apscheduler.scheduler:Scheduler started
ERROR:telegram.ext.dispatcher:No error handlers are registered, logging exception.
Traceback (most recent call last):
  File "/home/vartan/.local/lib/python3.8/site-packages/telegram/ext/dispatcher.py", line 425, in process_update
    handler.handle_update(update, self, check, context)
  File "/home/vartan/.local/lib/python3.8/site-packages/telegram/ext/handler.py", line 145, in handle_update
    return self.callback(update, context)
  File "bot.py", line 68, in get_plane
    mars=ephem.Sun()
AttributeError: module 'ephem' has no attribute 'Sun'
INFO:root:Бот стартовал
INFO:apscheduler.scheduler:Scheduler started
INFO:root:Бот стартовал
INFO:apscheduler.scheduler:Scheduler started
ERROR:telegram.ext.dispatcher:No error handlers are registered, logging exception.
Traceback (most recent call last):
  File "/home/vartan/.local/lib/python3.8/site-packages/telegram/ext/dispatcher.py", line 425, in process_update
    handler.handle_update(update, self, check, context)
  File "/home/vartan/.local/lib/python3.8/site-packages/telegram/ext/handler.py", line 145, in handle_update
    return self.callback(update, context)
  File "bot.py", line 16, in get_plane
    user_text = str(update.message.text)
AttributeError: 'NoneType' object has no attribute 'text'
INFO:root:Бот стартовал
INFO:apscheduler.scheduler:Scheduler started
ERROR:telegram.ext.dispatcher:No error handlers are registered, logging exception.
Traceback (most recent call last):
  File "/home/vartan/.local/lib/python3.8/site-packages/telegram/ext/dispatcher.py", line 425, in process_update
    handler.handle_update(update, self, check, context)
  File "/home/vartan/.local/lib/python3.8/site-packages/telegram/ext/handler.py", line 145, in handle_update
    return self.callback(update, context)
  File "bot.py", line 68, in get_plane
    mars=ephe.Sun()
AttributeError: module 'ephem' has no attribute 'Sun'
INFO:root:Бот стартовал
INFO:apscheduler.scheduler:Scheduler started
ERROR:telegram.ext.dispatcher:No error handlers are registered, logging exception.
Traceback (most recent call last):
  File "/home/vartan/.local/lib/python3.8/site-packages/telegram/ext/dispatcher.py", line 425, in process_update
    handler.handle_update(update, self, check, context)
  File "/home/vartan/.local/lib/python3.8/site-packages/telegram/ext/handler.py", line 145, in handle_update
    return self.callback(update, context)
  File "bot.py", line 68, in get_plane
    mars=ephe.Sun()
AttributeError: module 'ephem' has no attribute 'Sun'
INFO:root:Бот стартовал
INFO:apscheduler.scheduler:Scheduler started
